ERRORES EN PARTITION_SIMUL.R
Error in lda.default(x, grouping, ...) : 
  variables 1 2 3 appear to be constant within groups
Error in dimnames(x) <- dn : 
  la longitud de 'dimnames' [2] no es igual a la extensión del arreglo
Calls: colnames<-
Ejecución interrumpida
---------------------------------------

Error in solve.default(AP, c(c.x, c.y)) : 
  sistema es computacionalmente singular: número de condición recíproco = 4.39545e-17
Además: There were 35 warnings (use warnings() to see them)

-------------------------------------------------------------------------------

ERROR EN PARTITIONFUNCTIONS.PY
Traceback (most recent call last):
  File "/home/ruben/.local/lib/python3.8/site-packages/pandas/core/indexes/base.py", line 3802, in get_loc
    return self._engine.get_loc(casted_key)
  File "pandas/_libs/index.pyx", line 138, in pandas._libs.index.IndexEngine.get_loc
  File "pandas/_libs/index.pyx", line 165, in pandas._libs.index.IndexEngine.get_loc
  File "pandas/_libs/hashtable_class_helper.pxi", line 2263, in pandas._libs.hashtable.Int64HashTable.get_item
  File "pandas/_libs/hashtable_class_helper.pxi", line 2273, in pandas._libs.hashtable.Int64HashTable.get_item
KeyError: 1

The above exception was the direct cause of the following exception:

Traceback (most recent call last):
  File "partitionfunctions_python.py", line 235, in <module>
    randomPartition = create_random_partition(dataset["trainset"], dataset["trainclasses"], 3)
  File "partitionfunctions_python.py", line 71, in create_random_partition
    groupsList[i] = groups.xs(i + 1, level = "classes")
  File "/home/ruben/.local/lib/python3.8/site-packages/pandas/core/generic.py", line 4028, in xs
    loc, new_ax = labels.get_loc_level(key, level=level, drop_level=drop_level)
  File "/home/ruben/.local/lib/python3.8/site-packages/pandas/core/indexes/multi.py", line 3019, in get_loc_level
    loc, mi = self._get_loc_level(key, level=level)
  File "/home/ruben/.local/lib/python3.8/site-packages/pandas/core/indexes/multi.py", line 3160, in _get_loc_level
    indexer = self._get_level_indexer(key, level=level)
  File "/home/ruben/.local/lib/python3.8/site-packages/pandas/core/indexes/multi.py", line 3263, in _get_level_indexer
    idx = self._get_loc_single_level_index(level_index, key)
  File "/home/ruben/.local/lib/python3.8/site-packages/pandas/core/indexes/multi.py", line 2849, in _get_loc_single_level_index
    return level_index.get_loc(key)
  File "/home/ruben/.local/lib/python3.8/site-packages/pandas/core/indexes/base.py", line 3804, in get_loc
    raise KeyError(key) from err
KeyError: 1